2017-11-17 09:50:31,792 [Thread-21:123145500323840] [django.request:135] [exception:handle_uncaught_exception] [ERROR]- Internal Server Error: /user/info/
Traceback (most recent call last):
  File "/Users/zhanlingjie/Documents/virEnv/GPapp/lib/python3.4/site-packages/django/core/handlers/exception.py", line 41, in inner
    response = get_response(request)
  File "/Users/zhanlingjie/Documents/virEnv/GPapp/lib/python3.4/site-packages/django/core/handlers/base.py", line 187, in _get_response
    response = self.process_exception_by_middleware(e, request)
  File "/Users/zhanlingjie/Documents/virEnv/GPapp/lib/python3.4/site-packages/django/core/handlers/base.py", line 185, in _get_response
    response = wrapped_callback(request, *callback_args, **callback_kwargs)
  File "/Users/zhanlingjie/Documents/mypython/GG/z_user/views.py", line 21, in info
    return render_to_response('user/index.html')
  File "/Users/zhanlingjie/Documents/virEnv/GPapp/lib/python3.4/site-packages/django/shortcuts.py", line 21, in render_to_response
    content = loader.render_to_string(template_name, context, using=using)
  File "/Users/zhanlingjie/Documents/virEnv/GPapp/lib/python3.4/site-packages/django/template/loader.py", line 67, in render_to_string
    template = get_template(template_name, using=using)
  File "/Users/zhanlingjie/Documents/virEnv/GPapp/lib/python3.4/site-packages/django/template/loader.py", line 25, in get_template
    raise TemplateDoesNotExist(template_name, chain=chain)
django.template.exceptions.TemplateDoesNotExist: user/index.html
2018-03-18 06:06:05,150 [Thread-44:123145562763264] [django.request:135] [exception:handle_uncaught_exception] [ERROR]- Internal Server Error: /api/search_home
Traceback (most recent call last):
  File "/Users/zhanlingjie/Documents/virEnv/GPapp/lib/python3.4/site-packages/django/core/handlers/exception.py", line 41, in inner
    response = get_response(request)
  File "/Users/zhanlingjie/Documents/virEnv/GPapp/lib/python3.4/site-packages/django/core/handlers/base.py", line 187, in _get_response
    response = self.process_exception_by_middleware(e, request)
  File "/Users/zhanlingjie/Documents/virEnv/GPapp/lib/python3.4/site-packages/django/core/handlers/base.py", line 185, in _get_response
    response = wrapped_callback(request, *callback_args, **callback_kwargs)
  File "/Users/zhanlingjie/Documents/virEnv/GPapp/lib/python3.4/site-packages/django/views/decorators/csrf.py", line 58, in wrapped_view
    return view_func(*args, **kwargs)
  File "/Users/zhanlingjie/Documents/mypython/GG/api/views.py", line 21, in search_home
    db.gg_search.insert({'user': uid, 'content': content,  'create_time': int(time.time())})
  File "/Users/zhanlingjie/Documents/virEnv/GPapp/lib/python3.4/site-packages/pymongo/collection.py", line 2935, in insert
    check_keys, manipulate, write_concern)
  File "/Users/zhanlingjie/Documents/virEnv/GPapp/lib/python3.4/site-packages/pymongo/collection.py", line 598, in _insert
    bypass_doc_val, session)
  File "/Users/zhanlingjie/Documents/virEnv/GPapp/lib/python3.4/site-packages/pymongo/collection.py", line 578, in _insert_one
    True, _insert_command, session)
  File "/Users/zhanlingjie/Documents/virEnv/GPapp/lib/python3.4/site-packages/pymongo/mongo_client.py", line 1098, in _retryable_write
    with self._tmp_session(session) as s:
  File "/Library/Frameworks/Python.framework/Versions/3.4/lib/python3.4/contextlib.py", line 59, in __enter__
    return next(self.gen)
  File "/Users/zhanlingjie/Documents/virEnv/GPapp/lib/python3.4/site-packages/pymongo/mongo_client.py", line 1404, in _tmp_session
    s = self._ensure_session(session)
  File "/Users/zhanlingjie/Documents/virEnv/GPapp/lib/python3.4/site-packages/pymongo/mongo_client.py", line 1391, in _ensure_session
    return self.start_session(causal_consistency=False)
  File "/Users/zhanlingjie/Documents/virEnv/GPapp/lib/python3.4/site-packages/pymongo/mongo_client.py", line 1369, in start_session
    server_session = self._get_server_session()
  File "/Users/zhanlingjie/Documents/virEnv/GPapp/lib/python3.4/site-packages/pymongo/mongo_client.py", line 1377, in _get_server_session
    return self._topology.get_server_session()
  File "/Users/zhanlingjie/Documents/virEnv/GPapp/lib/python3.4/site-packages/pymongo/topology.py", line 416, in get_server_session
    None)
  File "/Users/zhanlingjie/Documents/virEnv/GPapp/lib/python3.4/site-packages/pymongo/topology.py", line 199, in _select_servers_loop
    self._error_message(selector))
pymongo.errors.ServerSelectionTimeoutError: 192.168.0.113:27017: [Errno 64] Host is down
2018-03-18 06:06:05,929 [Thread-45:123145546997760] [django.request:135] [exception:handle_uncaught_exception] [ERROR]- Internal Server Error: /api/search_home
Traceback (most recent call last):
  File "/Users/zhanlingjie/Documents/virEnv/GPapp/lib/python3.4/site-packages/django/core/handlers/exception.py", line 41, in inner
    response = get_response(request)
  File "/Users/zhanlingjie/Documents/virEnv/GPapp/lib/python3.4/site-packages/django/core/handlers/base.py", line 187, in _get_response
    response = self.process_exception_by_middleware(e, request)
  File "/Users/zhanlingjie/Documents/virEnv/GPapp/lib/python3.4/site-packages/django/core/handlers/base.py", line 185, in _get_response
    response = wrapped_callback(request, *callback_args, **callback_kwargs)
  File "/Users/zhanlingjie/Documents/virEnv/GPapp/lib/python3.4/site-packages/django/views/decorators/csrf.py", line 58, in wrapped_view
    return view_func(*args, **kwargs)
  File "/Users/zhanlingjie/Documents/mypython/GG/api/views.py", line 21, in search_home
    db.gg_search.insert({'user': uid, 'content': content,  'create_time': int(time.time())})
  File "/Users/zhanlingjie/Documents/virEnv/GPapp/lib/python3.4/site-packages/pymongo/collection.py", line 2935, in insert
    check_keys, manipulate, write_concern)
  File "/Users/zhanlingjie/Documents/virEnv/GPapp/lib/python3.4/site-packages/pymongo/collection.py", line 598, in _insert
    bypass_doc_val, session)
  File "/Users/zhanlingjie/Documents/virEnv/GPapp/lib/python3.4/site-packages/pymongo/collection.py", line 578, in _insert_one
    True, _insert_command, session)
  File "/Users/zhanlingjie/Documents/virEnv/GPapp/lib/python3.4/site-packages/pymongo/mongo_client.py", line 1098, in _retryable_write
    with self._tmp_session(session) as s:
  File "/Library/Frameworks/Python.framework/Versions/3.4/lib/python3.4/contextlib.py", line 59, in __enter__
    return next(self.gen)
  File "/Users/zhanlingjie/Documents/virEnv/GPapp/lib/python3.4/site-packages/pymongo/mongo_client.py", line 1404, in _tmp_session
    s = self._ensure_session(session)
  File "/Users/zhanlingjie/Documents/virEnv/GPapp/lib/python3.4/site-packages/pymongo/mongo_client.py", line 1391, in _ensure_session
    return self.start_session(causal_consistency=False)
  File "/Users/zhanlingjie/Documents/virEnv/GPapp/lib/python3.4/site-packages/pymongo/mongo_client.py", line 1369, in start_session
    server_session = self._get_server_session()
  File "/Users/zhanlingjie/Documents/virEnv/GPapp/lib/python3.4/site-packages/pymongo/mongo_client.py", line 1377, in _get_server_session
    return self._topology.get_server_session()
  File "/Users/zhanlingjie/Documents/virEnv/GPapp/lib/python3.4/site-packages/pymongo/topology.py", line 416, in get_server_session
    None)
  File "/Users/zhanlingjie/Documents/virEnv/GPapp/lib/python3.4/site-packages/pymongo/topology.py", line 199, in _select_servers_loop
    self._error_message(selector))
pymongo.errors.ServerSelectionTimeoutError: 192.168.0.113:27017: [Errno 64] Host is down
2018-03-18 06:06:06,156 [Thread-46:123145594294272] [django.request:135] [exception:handle_uncaught_exception] [ERROR]- Internal Server Error: /api/search_home
Traceback (most recent call last):
  File "/Users/zhanlingjie/Documents/virEnv/GPapp/lib/python3.4/site-packages/django/core/handlers/exception.py", line 41, in inner
    response = get_response(request)
  File "/Users/zhanlingjie/Documents/virEnv/GPapp/lib/python3.4/site-packages/django/core/handlers/base.py", line 187, in _get_response
    response = self.process_exception_by_middleware(e, request)
  File "/Users/zhanlingjie/Documents/virEnv/GPapp/lib/python3.4/site-packages/django/core/handlers/base.py", line 185, in _get_response
    response = wrapped_callback(request, *callback_args, **callback_kwargs)
  File "/Users/zhanlingjie/Documents/virEnv/GPapp/lib/python3.4/site-packages/django/views/decorators/csrf.py", line 58, in wrapped_view
    return view_func(*args, **kwargs)
  File "/Users/zhanlingjie/Documents/mypython/GG/api/views.py", line 21, in search_home
    db.gg_search.insert({'user': uid, 'content': content,  'create_time': int(time.time())})
  File "/Users/zhanlingjie/Documents/virEnv/GPapp/lib/python3.4/site-packages/pymongo/collection.py", line 2935, in insert
    check_keys, manipulate, write_concern)
  File "/Users/zhanlingjie/Documents/virEnv/GPapp/lib/python3.4/site-packages/pymongo/collection.py", line 598, in _insert
    bypass_doc_val, session)
  File "/Users/zhanlingjie/Documents/virEnv/GPapp/lib/python3.4/site-packages/pymongo/collection.py", line 578, in _insert_one
    True, _insert_command, session)
  File "/Users/zhanlingjie/Documents/virEnv/GPapp/lib/python3.4/site-packages/pymongo/mongo_client.py", line 1098, in _retryable_write
    with self._tmp_session(session) as s:
  File "/Library/Frameworks/Python.framework/Versions/3.4/lib/python3.4/contextlib.py", line 59, in __enter__
    return next(self.gen)
  File "/Users/zhanlingjie/Documents/virEnv/GPapp/lib/python3.4/site-packages/pymongo/mongo_client.py", line 1404, in _tmp_session
    s = self._ensure_session(session)
  File "/Users/zhanlingjie/Documents/virEnv/GPapp/lib/python3.4/site-packages/pymongo/mongo_client.py", line 1391, in _ensure_session
    return self.start_session(causal_consistency=False)
  File "/Users/zhanlingjie/Documents/virEnv/GPapp/lib/python3.4/site-packages/pymongo/mongo_client.py", line 1369, in start_session
    server_session = self._get_server_session()
  File "/Users/zhanlingjie/Documents/virEnv/GPapp/lib/python3.4/site-packages/pymongo/mongo_client.py", line 1377, in _get_server_session
    return self._topology.get_server_session()
  File "/Users/zhanlingjie/Documents/virEnv/GPapp/lib/python3.4/site-packages/pymongo/topology.py", line 416, in get_server_session
    None)
  File "/Users/zhanlingjie/Documents/virEnv/GPapp/lib/python3.4/site-packages/pymongo/topology.py", line 199, in _select_servers_loop
    self._error_message(selector))
pymongo.errors.ServerSelectionTimeoutError: 192.168.0.113:27017: [Errno 64] Host is down
2018-03-18 06:06:06,362 [Thread-47:123145615314944] [django.request:135] [exception:handle_uncaught_exception] [ERROR]- Internal Server Error: /api/search_home
Traceback (most recent call last):
  File "/Users/zhanlingjie/Documents/virEnv/GPapp/lib/python3.4/site-packages/django/core/handlers/exception.py", line 41, in inner
    response = get_response(request)
  File "/Users/zhanlingjie/Documents/virEnv/GPapp/lib/python3.4/site-packages/django/core/handlers/base.py", line 187, in _get_response
    response = self.process_exception_by_middleware(e, request)
  File "/Users/zhanlingjie/Documents/virEnv/GPapp/lib/python3.4/site-packages/django/core/handlers/base.py", line 185, in _get_response
    response = wrapped_callback(request, *callback_args, **callback_kwargs)
  File "/Users/zhanlingjie/Documents/virEnv/GPapp/lib/python3.4/site-packages/django/views/decorators/csrf.py", line 58, in wrapped_view
    return view_func(*args, **kwargs)
  File "/Users/zhanlingjie/Documents/mypython/GG/api/views.py", line 21, in search_home
    db.gg_search.insert({'user': uid, 'content': content,  'create_time': int(time.time())})
  File "/Users/zhanlingjie/Documents/virEnv/GPapp/lib/python3.4/site-packages/pymongo/collection.py", line 2935, in insert
    check_keys, manipulate, write_concern)
  File "/Users/zhanlingjie/Documents/virEnv/GPapp/lib/python3.4/site-packages/pymongo/collection.py", line 598, in _insert
    bypass_doc_val, session)
  File "/Users/zhanlingjie/Documents/virEnv/GPapp/lib/python3.4/site-packages/pymongo/collection.py", line 578, in _insert_one
    True, _insert_command, session)
  File "/Users/zhanlingjie/Documents/virEnv/GPapp/lib/python3.4/site-packages/pymongo/mongo_client.py", line 1098, in _retryable_write
    with self._tmp_session(session) as s:
  File "/Library/Frameworks/Python.framework/Versions/3.4/lib/python3.4/contextlib.py", line 59, in __enter__
    return next(self.gen)
  File "/Users/zhanlingjie/Documents/virEnv/GPapp/lib/python3.4/site-packages/pymongo/mongo_client.py", line 1404, in _tmp_session
    s = self._ensure_session(session)
  File "/Users/zhanlingjie/Documents/virEnv/GPapp/lib/python3.4/site-packages/pymongo/mongo_client.py", line 1391, in _ensure_session
    return self.start_session(causal_consistency=False)
  File "/Users/zhanlingjie/Documents/virEnv/GPapp/lib/python3.4/site-packages/pymongo/mongo_client.py", line 1369, in start_session
    server_session = self._get_server_session()
  File "/Users/zhanlingjie/Documents/virEnv/GPapp/lib/python3.4/site-packages/pymongo/mongo_client.py", line 1377, in _get_server_session
    return self._topology.get_server_session()
  File "/Users/zhanlingjie/Documents/virEnv/GPapp/lib/python3.4/site-packages/pymongo/topology.py", line 416, in get_server_session
    None)
  File "/Users/zhanlingjie/Documents/virEnv/GPapp/lib/python3.4/site-packages/pymongo/topology.py", line 199, in _select_servers_loop
    self._error_message(selector))
pymongo.errors.ServerSelectionTimeoutError: 192.168.0.113:27017: [Errno 64] Host is down
2018-03-18 06:06:08,268 [Thread-48:123145636335616] [django.request:135] [exception:handle_uncaught_exception] [ERROR]- Internal Server Error: /api/search_home
Traceback (most recent call last):
  File "/Users/zhanlingjie/Documents/virEnv/GPapp/lib/python3.4/site-packages/django/core/handlers/exception.py", line 41, in inner
    response = get_response(request)
  File "/Users/zhanlingjie/Documents/virEnv/GPapp/lib/python3.4/site-packages/django/core/handlers/base.py", line 187, in _get_response
    response = self.process_exception_by_middleware(e, request)
  File "/Users/zhanlingjie/Documents/virEnv/GPapp/lib/python3.4/site-packages/django/core/handlers/base.py", line 185, in _get_response
    response = wrapped_callback(request, *callback_args, **callback_kwargs)
  File "/Users/zhanlingjie/Documents/virEnv/GPapp/lib/python3.4/site-packages/django/views/decorators/csrf.py", line 58, in wrapped_view
    return view_func(*args, **kwargs)
  File "/Users/zhanlingjie/Documents/mypython/GG/api/views.py", line 21, in search_home
    db.gg_search.insert({'user': uid, 'content': content,  'create_time': int(time.time())})
  File "/Users/zhanlingjie/Documents/virEnv/GPapp/lib/python3.4/site-packages/pymongo/collection.py", line 2935, in insert
    check_keys, manipulate, write_concern)
  File "/Users/zhanlingjie/Documents/virEnv/GPapp/lib/python3.4/site-packages/pymongo/collection.py", line 598, in _insert
    bypass_doc_val, session)
  File "/Users/zhanlingjie/Documents/virEnv/GPapp/lib/python3.4/site-packages/pymongo/collection.py", line 578, in _insert_one
    True, _insert_command, session)
  File "/Users/zhanlingjie/Documents/virEnv/GPapp/lib/python3.4/site-packages/pymongo/mongo_client.py", line 1098, in _retryable_write
    with self._tmp_session(session) as s:
  File "/Library/Frameworks/Python.framework/Versions/3.4/lib/python3.4/contextlib.py", line 59, in __enter__
    return next(self.gen)
  File "/Users/zhanlingjie/Documents/virEnv/GPapp/lib/python3.4/site-packages/pymongo/mongo_client.py", line 1404, in _tmp_session
    s = self._ensure_session(session)
  File "/Users/zhanlingjie/Documents/virEnv/GPapp/lib/python3.4/site-packages/pymongo/mongo_client.py", line 1391, in _ensure_session
    return self.start_session(causal_consistency=False)
  File "/Users/zhanlingjie/Documents/virEnv/GPapp/lib/python3.4/site-packages/pymongo/mongo_client.py", line 1369, in start_session
    server_session = self._get_server_session()
  File "/Users/zhanlingjie/Documents/virEnv/GPapp/lib/python3.4/site-packages/pymongo/mongo_client.py", line 1377, in _get_server_session
    return self._topology.get_server_session()
  File "/Users/zhanlingjie/Documents/virEnv/GPapp/lib/python3.4/site-packages/pymongo/topology.py", line 416, in get_server_session
    None)
  File "/Users/zhanlingjie/Documents/virEnv/GPapp/lib/python3.4/site-packages/pymongo/topology.py", line 199, in _select_servers_loop
    self._error_message(selector))
pymongo.errors.ServerSelectionTimeoutError: 192.168.0.113:27017: [Errno 64] Host is down
2018-03-18 06:06:18,961 [Thread-49:123145541742592] [django.request:135] [exception:handle_uncaught_exception] [ERROR]- Internal Server Error: /api/search_home
Traceback (most recent call last):
  File "/Users/zhanlingjie/Documents/virEnv/GPapp/lib/python3.4/site-packages/django/core/handlers/exception.py", line 41, in inner
    response = get_response(request)
  File "/Users/zhanlingjie/Documents/virEnv/GPapp/lib/python3.4/site-packages/django/core/handlers/base.py", line 187, in _get_response
    response = self.process_exception_by_middleware(e, request)
  File "/Users/zhanlingjie/Documents/virEnv/GPapp/lib/python3.4/site-packages/django/core/handlers/base.py", line 185, in _get_response
    response = wrapped_callback(request, *callback_args, **callback_kwargs)
  File "/Users/zhanlingjie/Documents/virEnv/GPapp/lib/python3.4/site-packages/django/views/decorators/csrf.py", line 58, in wrapped_view
    return view_func(*args, **kwargs)
  File "/Users/zhanlingjie/Documents/mypython/GG/api/views.py", line 21, in search_home
    db.gg_search.insert({'user': uid, 'content': content,  'create_time': int(time.time())})
  File "/Users/zhanlingjie/Documents/virEnv/GPapp/lib/python3.4/site-packages/pymongo/collection.py", line 2935, in insert
    check_keys, manipulate, write_concern)
  File "/Users/zhanlingjie/Documents/virEnv/GPapp/lib/python3.4/site-packages/pymongo/collection.py", line 598, in _insert
    bypass_doc_val, session)
  File "/Users/zhanlingjie/Documents/virEnv/GPapp/lib/python3.4/site-packages/pymongo/collection.py", line 578, in _insert_one
    True, _insert_command, session)
  File "/Users/zhanlingjie/Documents/virEnv/GPapp/lib/python3.4/site-packages/pymongo/mongo_client.py", line 1098, in _retryable_write
    with self._tmp_session(session) as s:
  File "/Library/Frameworks/Python.framework/Versions/3.4/lib/python3.4/contextlib.py", line 59, in __enter__
    return next(self.gen)
  File "/Users/zhanlingjie/Documents/virEnv/GPapp/lib/python3.4/site-packages/pymongo/mongo_client.py", line 1404, in _tmp_session
    s = self._ensure_session(session)
  File "/Users/zhanlingjie/Documents/virEnv/GPapp/lib/python3.4/site-packages/pymongo/mongo_client.py", line 1391, in _ensure_session
    return self.start_session(causal_consistency=False)
  File "/Users/zhanlingjie/Documents/virEnv/GPapp/lib/python3.4/site-packages/pymongo/mongo_client.py", line 1369, in start_session
    server_session = self._get_server_session()
  File "/Users/zhanlingjie/Documents/virEnv/GPapp/lib/python3.4/site-packages/pymongo/mongo_client.py", line 1377, in _get_server_session
    return self._topology.get_server_session()
  File "/Users/zhanlingjie/Documents/virEnv/GPapp/lib/python3.4/site-packages/pymongo/topology.py", line 416, in get_server_session
    None)
  File "/Users/zhanlingjie/Documents/virEnv/GPapp/lib/python3.4/site-packages/pymongo/topology.py", line 199, in _select_servers_loop
    self._error_message(selector))
pymongo.errors.ServerSelectionTimeoutError: 192.168.0.113:27017: [Errno 64] Host is down
